Workbook

Sheet README
B1: DPROPERTY OS - FINANCIAL MODEL
B3: Version: v0.7 (working) Last built: 2026-07-05 Owner: Esteban
B4: Basis: collected-GCI royalty on GROSS-INTO-COMPANY, 30k/40k staged launch fee, Dproperty Select fixed pct of sale price.
B6: COMMISSION WATERFALL (local franchise sale)
B7: 5% commission charged -> 50/50 with external advisors -> 2.5% enters company.
B8: Of what enters: 35% seller, 10% sales director, 55% franchise net.
B9: Royalty (6%) + Network & Brand Fund (1.5%) are charged on GROSS-INTO-COMPANY (the 2.5%),
B10: NOT on franchise net - so a franchise cannot lower royalty by inflating agent pay.
B12: HOW TO USE
B13: 1. Edit only the yellow cells on 'Assumptions' and the yellow cost rows on 'Model'.
B14: 2. Everything else on 'Model' is a live formula and recalculates when you open in Excel.
B15: 3. Blue rows = section headers. Grey rows = totals.
... B31: 4. Minimum royalty floor amount (750/mo placeholder).

Sheet Assumptions
B1: ASSUMPTIONS - edit the yellow cells
B3: Unit price (USD) | C3: 300000 | D3: Average unit price
B4: Local commission rate | C4: 0.05 | D4: Set 0.0075 to test the 0.75pct case
B5: Royalty rate | C5: 0.06 | D5: On gross-into-company
B6: Network & Brand Fund | C6: 0.015 | D6: On gross-into-company
B7: Total local take | C7: =C5+C6 | D7: Royalty + Fund
B8: Launch fee - founding | C8: 30000 | D8: First 5 franchises
B9: Launch fee - mature | C9: 40000 | D9: After 5 successful franchises
B10: OS fee / month | C10: 1000 | D10: Per franchise
B11: Min royalty floor / month | C11: 750 | D11: From month 7 (placeholder)
B12: Dproperty Select commission (model) | C12: 0.05 | D12: Model at 5pct; upside kept by HQ
B13: Select payout - branded | C13: 0.025 | D13: pct of sale price to franchisee
B14: Select payout - white-label | C14: 0.02 | D14: pct of sale price to partner
B15: Units per franchise / year | C15: 50 | D15: Full-productivity assumption
B16: Local sales mix | C16: 0.7 | D16: Share of units that are local
B17: Dproperty Select mix | C17: 0.3 | D17: Share of units that are Select
B18: White-label setup (avg) | C18: 12000 | D18: Blend of starter/growth
B19: White-label monthly (avg) | C19: 1800 | D19: Blend of starter/growth
... B23: External advisor share | C23: 0.5 | D23: Co-broke split; company keeps the rest
B24: Gross commission / unit (5pct) | C24: =C3*C4 | D24: Price x commission
B25: Commission into company / unit | C25: =C24*(1-C23) | D25: ROYALTY BASE (after co-broke)
B26: Seller share (of company comm) | C26: 0.35 | D26: Franchise internal split
B27: Sales director share | C27: 0.1 | D27: Franchise internal split
B28: Franchise net share | C28: =1-C26-C27 | D28: Remaining after seller+director
B29: Franchise net / unit | C29: =C25*C28 | D29: Franchise take-home per local unit
B30: Select HQ retained - branded | C30: =C24-C3*C13 | D30: Commission minus branded payout
B31: Select HQ retained - white-label | C31: =C24-C3*C14 | D31: Commission minus WL payout

Sheet Model
B1: DPROPERTY OS - FINANCIAL MODEL v0.7 (blue=headers, grey=totals, yellow=editable)
B3: Line | C3: Year 1 | D3: Year 2 | E3: Year 3 | F3: Year 4 | G3: Year 5
B4: COUNTS
B5: Branded franchises (EOY) | C5: 0 | D5: 1 | E5: 2 | F5: 3 | G5: 5
B6: Branded - new this year | C6: =C5 | D6: =D5-C5 | E6: =E5-D5 | F6: =F5-E5 | G6: =G5-F5
B7: Branded - active (avg) | C7: =(0+C5)/2 | D7: =(C5+D5)/2 | E7: =(D5+E5)/2 | F7: =(E5+F5)/2 | G7: =(F5+G5)/2
B8: White-label (EOY) | C8: 2 | D8: 5 | E8: 10 | F8: 15 | G8: 20
B9: White-label - new this year | C9: =C8 | D9: =D8-C8 | E9: =E8-D8 | F9: =F8-E8 | G9: =G8-F8
B10: White-label - active (avg) | C10: =(0+C8)/2 | D10: =(C8+D8)/2 | E10: =(D8+E8)/2 | F10: =(E8+F8)/2 | G10: =(F8+G8)/2
B11: Developer projects / year | C11: 1 | D11: 3 | E11: 6 | F11: 10 | G11: 15
B12: Ramp factor (0-1) | C12: 0.5 | D12: 0.6 | E12: 0.7 | F12: 0.75 | G12: 0.8
B14: REVENUE (USD)
B15: Franchise launch fees | C15: =C6*Assumptions!$C$8 | D15: =D6*Assumptions!$C$8 | E15: =E6*Assumptions!$C$8 | F15: =F6*Assumptions!$C$8 | G15: =G6*Assumptions!$C$8
B16: Franchise OS fees | C16: =C7*Assumptions!$C$10*12 | D16: =D7*Assumptions!$C$10*12 | E16: =E7*Assumptions!$C$10*12 | F16: =F7*Assumptions!$C$10*12 | G16: =G7*Assumptions!$C$10*12
B17: Local royalty + Fund (on gross-into-company) | C17: =C7*Assumptions!$C$15*Assumptions!$C$16*Assumptions!$C$25*Assumptions!$C$7*C12 | D17: =D7*Assumptions!$C$15*Assumptions!$C$16*Assumptions!$C$25*Assumptions!$C$7*D12 | E17: =E7*Assumptions!$C$15*Assumptions!$C$16*Assumptions!$C$25*Assumptions!$C$7*E12 | F17: =F7*Assumptions!$C$15*Assumptions!$C$16*Assumptions!$C$25*Assumptions!$C$7*F12 | G17: =G7*Assumptions!$C$15*Assumptions!$C$16*Assumptions!$C$25*Assumptions!$C$7*G12
B18: Dproperty Select - HQ retained | C18: =C7*Assumptions!$C$15*Assumptions!$C$17*Assumptions!$C$30*C12 | D18: =D7*Assumptions!$C$15*Assumptions!$C$17*Assumptions!$C$30*D12 | E18: =E7*Assumptions!$C$15*Assumptions!$C$17*Assumptions!$C$30*E12 | F18: =F7*Assumptions!$C$15*Assumptions!$C$17*Assumptions!$C$30*F12 | G18: =G7*Assumptions!$C$15*Assumptions!$C$17*Assumptions!$C$30*G12
B19: White-label setup fees | C19: =C9*Assumptions!$C$18 | D19: =D9*Assumptions!$C$18 | E19: =E9*Assumptions!$C$18 | F19: =F9*Assumptions!$C$18 | G19: =G9*Assumptions!$C$18
B20: White-label recurring | C20: =C10*Assumptions!$C$19*12 | D20: =D10*Assumptions!$C$19*12 | E20: =E10*Assumptions!$C$19*12 | F20: =F10*Assumptions!$C$19*12 | G20: =G10*Assumptions!$C$19*12
B21: GoHighLevel resale margin | C21: =(C7+C10)*Assumptions!$C$20*12 | D21: =(D7+D10)*Assumptions!$C$20*12 | E21: =(E7+E10)*Assumptions!$C$20*12 | F21: =(F7+F10)*Assumptions!$C$20*12 | G21: =(G7+G10)*Assumptions!$C$20*12
B22: Developer Sales OS | C22: =C11*Assumptions!$C$21 | D22: =D11*Assumptions!$C$21 | E22: =E11*Assumptions!$C$21 | F22: =F11*Assumptions!$C$21 | G22: =G11*Assumptions!$C$21
B23: TOTAL REVENUE | C23: =SUM(C15:C22) | D23: =SUM(D15:D22) | E23: =SUM(E15:E22) | F23: =SUM(F15:F22) | G23: =SUM(G15:G22)
B25: OPERATING COSTS (USD) - editable planning estimates
B26: Salaries (founders + team) | C26: 150000 | D26: 220000 | E26: 300000 | F26: 400000 | G26: 500000
B27: Product / technology | C27: 80000 | D27: 70000 | E27: 80000 | F27: 90000 | G27: 100000
B28: Legal / compliance | C28: 60000 | D28: 40000 | E28: 40000 | F28: 40000 | G28: 40000
B29: Training / content | C29: 40000 | D29: 30000 | E29: 30000 | F29: 35000 | G29: 40000
B30: Customer success / implementation | C30: 30000 | D30: 50000 | E30: 70000 | F30: 90000 | G30: 110000
B31: Sales / BD / travel | C31: 40000 | D31: 50000 | E31: 60000 | F31: 70000 | G31: 80000
B32: Hosting / tools / admin | C32: 30000 | D32: 35000 | E32: 45000 | F32: 55000 | G32: 65000
B33: Contingency | C33: 15000 | D33: 15000 | E33: 20000 | F33: 25000 | G33: 30000
B34: TOTAL OPEX | C34: =SUM(C26:C33) | D34: =SUM(D26:D33) | E34: =SUM(E26:E33) | F34: =SUM(F26:F33) | G34: =SUM(G26:G33)
B36: EBITDA | C36: =C23-C34 | D36: =D23-D34 | E36: =E23-E34 | F36: =F23-F34 | G36: =G23-G34
B37: EBITDA margin | C37: =IFERROR(C36/C23,0) | D37: =IFERROR(D36/D23,0) | E37: =IFERROR(E36/E23,0) | F37: =IFERROR(F36/F23,0) | G37: =IFERROR(G36/G23,0)
B39: LOCAL DEAL WATERFALL (reference, per unit)
B40: Gross commission (5%) | C40: =Assumptions!$C$24
B41: Less external advisors (50%) | C41: =-Assumptions!$C$24*Assumptions!$C$23
B42: Into company (royalty base) | C42: =Assumptions!$C$25
B43: Seller (35%) | C43: =-Assumptions!$C$25*Assumptions!$C$26
B44: Sales director (10%) | C44: =-Assumptions!$C$25*Assumptions!$C$27
B45: Franchise net | C45: =Assumptions!$C$29
...
